<mujoco model="dog">
  <option iterations="50" timestep="0.001" solver="PGS" gravity="0 0 -9.81" cone="elliptic"/>

  <compiler angle="radian" meshdir="meshes" eulerseq="zyx" autolimits="true" />

  <default>
    <joint limited="true" damping="0.01" armature="0.06" frictionloss="0.01" />
    <geom condim="4" contype="1" conaffinity="15" friction="0.9 0.2 0.2" solref="0.001 2" />
    <motor ctrllimited="true" />
    <equality solref="0.001 2" />
    <default class="visualgeom">
      <geom material="visualgeom" condim="1" contype="0" conaffinity="0" />
    </default>
  </default>

  <asset>
    <mesh name="base_link" content_type="model/stl" file="base_link.stl" />
    <mesh name="fr_hip_Link" content_type="model/stl" file="fr_hip_Link.stl" />
    <mesh name="fr_knee_Link" content_type="model/stl" file="fr_knee_Link.stl" />
    <mesh name="fr_thigh_Link" content_type="model/stl" file="fr_thigh_Link.stl" />
    <mesh name="fl_hip_Link" content_type="model/stl" file="fl_hip_Link.stl" />
    <mesh name="fl_knee_Link" content_type="model/stl" file="fl_knee_Link.stl" />
    <mesh name="fl_thigh_Link" content_type="model/stl" file="fl_thigh_Link.stl" />
    <mesh name="br_hip_Link" content_type="model/stl" file="br_hip_Link.stl" />
    <mesh name="br_knee_Link" content_type="model/stl" file="br_knee_Link.stl" />
    <mesh name="br_thigh_Link" content_type="model/stl" file="br_thigh_Link.stl" />
    <mesh name="bl_hip_Link" content_type="model/stl" file="bl_hip_Link.stl" />
    <mesh name="bl_knee_Link" content_type="model/stl" file="bl_knee_Link.stl" />
    <mesh name="bl_thigh_Link" content_type="model/stl" file="bl_thigh_Link.stl" />
    <texture name="texplane" type="2d" builtin="checker" rgb1=".0 .0 .0" rgb2=".8 .8 .8" width="100" height="100" />
    <material name="matplane" reflectance="0." texture="texplane" texrepeat="1 1" texuniform="true" />
    <material name="visualgeom" rgba="0.5 0.9 0.2 1" />
  </asset>

  <worldbody>
    <light directional="true" diffuse="0.4 0.4 0.4" specular="0.1 0.1 0.1" pos="0 0 5.0" dir="0 0 -1" castshadow="false" />
    <geom name="ground" type="plane" pos="0 0 0" size="100 100 0.001" quat="1 0 0 0" material="matplane" condim="3" conaffinity="15" />
    <camera name="track_body" mode="targetbody" target="root" pos="0 -3.0 0.6" xyaxes="1 0 0 0 0 1"  />
    <body name="root" pos="0 0 0.43969776660575016" quat="1 0 0 0">
      <freejoint name="root" />
      <site name="imu_sensor" size="0.01" pos="0 0 0" euler="0 0 0"/>
      <geom type="mesh" rgba="1 0.513726 0.835294 1" mesh="base_link" contype="1" conaffinity="0" density="0" group="1" class="visualgeom" />
      <geom type="mesh" rgba="1 0.513726 0.835294 1" mesh="base_link" />
      <body name="fr_hip_Link" pos="0.16425 -0.056271 0.0065998" quat="1 0 0 -9.5735e-05">
        <inertial pos="0.0627766 -0.00732402 0.0013735" quat="0.538805 0.458423 0.45746 0.538765" mass="1.22882" diaginertia="0.00102653 0.000645444 0.000630915" />
        <joint name="fr_hip_joint" pos="0 0 0" axis="1 0 0" range="-1.05 1.05" actuatorfrcrange="-40 40" damping="0.01" frictionloss="1" />
        <geom type="mesh" rgba="1 0.301961 0.137255 1" mesh="fr_hip_Link" contype="1" conaffinity="0" density="0" group="1" class="visualgeom" />
        <body name="fr_knee_Link" pos="0.093 -0.0211 0.0019065">
          <inertial pos="-0.00412725 -0.045548 -0.0223222" quat="0.69674 0.00273397 0.0699748 0.713897" mass="0.954666" diaginertia="0.00244391 0.00187644 0.000693254" />
          <joint name="fr_knee_joint" pos="0 0 0" axis="0 1 0" range="-0.7 1.4" actuatorfrcrange="-40 40" damping="0.01" frictionloss="1" />
          <geom type="mesh" rgba="0.898039 0.917647 0.929412 1" mesh="fr_knee_Link" contype="1" conaffinity="0" density="0" group="1" class="visualgeom" />
          <body name="fr_thigh_Link" pos="0 -0.0609 -0.20735">
            <inertial pos="0.00802916 1.74427e-05 -0.100093" quat="0.707259 -0.0101363 -0.0102571 0.706807" mass="0.102313" diaginertia="0.000640822 0.000632066 9.70631e-06" />
            <joint name="fr_thigh_joint" pos="0 0 0" axis="0 1 0" range="-2.44 -0.83" actuatorfrcrange="-40 40" damping="0.01" frictionloss="1" />
            <geom type="mesh" rgba="0.498039 0.498039 0.498039 1" mesh="fr_thigh_Link" contype="1" conaffinity="0" density="0" group="1" class="visualgeom" />
          </body>
        </body>
      </body>
      <body name="fl_hip_Link" pos="0.16478 0.056229 0.0065999" quat="1 0 0 -9.5735e-05">
        <inertial pos="0.0627765 0.00765302 -0.00137352" quat="0.457446 0.538777 0.538816 0.458409" mass="1.22882" diaginertia="0.00102653 0.000645443 0.000630915" />
        <joint name="fl_hip_joint" pos="0 0 0" axis="1 0 0" range="-1.05 1.05" actuatorfrcrange="-40 40" damping="0.01" frictionloss="1" />
        <geom type="mesh" rgba="0.529412 0.54902 0.54902 1" mesh="fl_hip_Link" contype="1" conaffinity="0" density="0" group="1" class="visualgeom" />
        <body name="fl_knee_Link" pos="0.093 0.0216 -0.0019065">
          <inertial pos="-0.00405629 0.0455088 -0.0222996" quat="0.713839 0.0719599 0.00476521 0.696586" mass="0.95433" diaginertia="0.00245012 0.00188281 0.000693078" />
          <joint name="fl_knee_joint" pos="0 0 0" axis="0 1 0" range="-0.7 1.4" actuatorfrcrange="-40 40" damping="0.01" frictionloss="1" />
          <geom type="mesh" rgba="0.898039 0.917647 0.929412 1" mesh="fl_knee_Link" contype="1" conaffinity="0" density="0" group="1" class="visualgeom" />
          <body name="fl_thigh_Link" pos="0 0.0689 -0.20735">
            <inertial pos="0.00802923 -0.00799683 -0.100093" quat="0.706763 -0.0102894 -0.0101003 0.707304" mass="0.102313" diaginertia="0.00064089 0.000632134 9.70642e-06" />
            <joint name="fl_thigh_joint" pos="0 0 0" axis="0 1 0" range="-2.44 -0.83" actuatorfrcrange="-40 40" damping="0.01" frictionloss="1" />
            <geom type="mesh" rgba="0.498039 0.498039 0.498039 1" mesh="fl_thigh_Link" contype="1" conaffinity="0" density="0" group="1" class="visualgeom" />
          </body>
        </body>
      </body>
      <body name="br_hip_Link" pos="-0.16795 -0.056228 0.0067" quat="1 0 0 -9.5735e-05">
        <inertial pos="-0.0627764 -0.00732403 -0.00137343" quat="0.538765 0.45746 0.458423 0.538805" mass="1.22881" diaginertia="0.00102653 0.000645443 0.000630914" />
        <joint name="br_hip_joint" pos="0 0 0" axis="1 0 0" range="-1.05 1.05" actuatorfrcrange="-40 40" damping="0.01" frictionloss="1" />
        <geom type="mesh" rgba="1 0.301961 0.137255 1" mesh="br_hip_Link" contype="1" conaffinity="0" density="0" group="1" class="visualgeom" />
        <body name="br_knee_Link" pos="-0.093 -0.0211 -0.0019064">
          <inertial pos="-0.00400975 -0.0454196 -0.0217569" quat="0.696712 0.00261388 0.0698647 0.713936" mass="0.942891" diaginertia="0.0024432 0.00187601 0.000692868" />
          <joint name="br_knee_joint" pos="0 0 0" axis="0 1 0" range="-0.7 1.4" actuatorfrcrange="-40 40" damping="0.01" frictionloss="1" />
          <geom type="mesh" rgba="0.898039 0.917647 0.929412 1" mesh="br_knee_Link" contype="1" conaffinity="0" density="0" group="1" class="visualgeom" />
          <body name="br_thigh_Link" pos="0 -0.0609 -0.20735">
            <inertial pos="0.00802916 1.74427e-05 -0.100093" quat="0.707259 -0.0101363 -0.0102571 0.706807" mass="0.102313" diaginertia="0.000640822 0.000632066 9.70631e-06" />
            <joint name="br_thigh_joint" pos="0 0 0" axis="0 1 0" range="-2.44 -0.83" actuatorfrcrange="-40 40" damping="0.01" frictionloss="1" />
            <geom type="mesh" rgba="0.498039 0.498039 0.498039 1" mesh="br_thigh_Link" contype="1" conaffinity="0" density="0" group="1" class="visualgeom" />
          </body>
        </body>
      </body>
      <body name="bl_hip_Link" pos="-0.16792 0.056272 0.0067" quat="1 0 0 -9.5735e-05">
        <inertial pos="-0.0627764 0.00732402 0.00137344" quat="0.458416 0.53881 0.538771 0.457453" mass="1.22882" diaginertia="0.00102653 0.000645444 0.000630915" />
        <joint name="bl_hip_joint" pos="0 0 0" axis="1 0 0" range="-1.05 1.05" actuatorfrcrange="-40 40" damping="0.01" frictionloss="1" />
        <geom type="mesh" rgba="0.529412 0.54902 0.54902 1" mesh="bl_hip_Link" contype="1" conaffinity="0" density="0" group="1" class="visualgeom" />
        <body name="bl_knee_Link" pos="-0.093 0.0211 0.0019064">
          <inertial pos="-0.00409869 0.045546 -0.0223093" quat="0.713755 0.0722354 0.00503051 0.696642" mass="0.95433" diaginertia="0.00245011 0.0018827 0.000693194" />
          <joint name="bl_knee_joint" pos="0 0 0" axis="0 1 0" range="-0.7 1.4" actuatorfrcrange="-40 40" damping="0.01" frictionloss="1" />
          <geom type="mesh" rgba="0.898039 0.917647 0.929412 1" mesh="bl_knee_Link" contype="1" conaffinity="0" density="0" group="1" class="visualgeom" />
          <body name="bl_thigh_Link" pos="0 0.0689 -0.20735">
            <inertial pos="0.00802923 -0.00799683 -0.100093" quat="0.706763 -0.0102894 -0.0101003 0.707304" mass="0.102313" diaginertia="0.00064089 0.000632134 9.70642e-06" />
            <joint name="bl_thigh_joint" pos="0 0 0" axis="0 1 0" range="-2.44 -0.83" actuatorfrcrange="-40 40" damping="0.01" frictionloss="1" />
            <geom type="mesh" rgba="0.498039 0.498039 0.498039 1" mesh="bl_thigh_Link" contype="1" conaffinity="0" density="0" group="1" class="visualgeom" />
          </body>
        </body>
      </body>
    </body>




    <!-- 障碍：
     <geom type="box" size="1.5  0.1 0.5" pos="-0.5 1 0.5" rgba="0 1 0 1"/>
     <geom type="box" size="2.2 0.1 0.5" pos="0.2 -1 0.5" rgba="0 1 0 1"/>
     <geom type="box" size="0.1 1 0.5" pos="-2 0 0.5" rgba="0 1 0 1"/>

     <geom type="box" size="0.1 1.5 0.5" pos="1 2.5 0.5" rgba="0 1 0 1"/>
     <geom type="box" size="0.1 2 0.5" pos="2.5 1 0.5" rgba="0 1 0 1"/>
     
     <geom type="box" size="0.1 2 0.5" pos="2.5 1 0.5" rgba="0 1 0 1"/>
     <geom type="box" size="0.1 2 0.5" pos="2.5 1 0.5" rgba="0 1 0 1"/>

     <geom type="box" size="2 0.1 0.5" pos="3 4 0.5" rgba="0 1 0 1"/>
     <geom type="box" size="2 0.1 0.5" pos="4.5 3 0.5" rgba="0 1 0 1"/> -->
     
  </worldbody>
    <keyframe>
    <!-- 
       qpos 解释：
       前7个值 [0-6]: 根关节 (freejoint) -> 3个位置(x,y,z) + 4个四元数(w,x,y,z)
       后续的值 [7...]: 你的各个转动关节的角度 (单位：弧度)
    -->
    <key name="init_pose" 
         qpos="0 0 0.072 1 0 0 0    -0.61 0.88 -2.44    0.61 0.88 -2.44    -0.61 0.88 -2.44    0.61 0.88 -2.44" />
  </keyframe>

  <actuator>
    <motor name="fr_hip_joint" joint="fr_hip_joint" ctrllimited="true" ctrlrange="-40 40" gear="1" />
    <motor name="fr_knee_joint" joint="fr_knee_joint" ctrllimited="true" ctrlrange="-40 40" gear="1" />
    <motor name="fr_thigh_joint" joint="fr_thigh_joint" ctrllimited="true" ctrlrange="-40 40" gear="1" />
    <motor name="fl_hip_joint" joint="fl_hip_joint" ctrllimited="true" ctrlrange="-40 40" gear="1" />
    <motor name="fl_knee_joint" joint="fl_knee_joint" ctrllimited="true" ctrlrange="-40 40" gear="1" />
    <motor name="fl_thigh_joint" joint="fl_thigh_joint" ctrllimited="true" ctrlrange="-40 40" gear="1" />
    <motor name="br_hip_joint" joint="br_hip_joint" ctrllimited="true" ctrlrange="-40 40" gear="1" />
    <motor name="br_knee_joint" joint="br_knee_joint" ctrllimited="true" ctrlrange="-40 40" gear="1" />
    <motor name="br_thigh_joint" joint="br_thigh_joint" ctrllimited="true" ctrlrange="-40 40" gear="1" />
    <motor name="bl_hip_joint" joint="bl_hip_joint" ctrllimited="true" ctrlrange="-40 40" gear="1" />
    <motor name="bl_knee_joint" joint="bl_knee_joint" ctrllimited="true" ctrlrange="-40 40" gear="1" />
    <motor name="bl_thigh_joint" joint="bl_thigh_joint" ctrllimited="true" ctrlrange="-40 40" gear="1" />
  </actuator>

  <sensor>
    <actuatorpos name="fr_hip_joint_p" actuator="fr_hip_joint" />
    <actuatorvel name="fr_hip_joint_v" actuator="fr_hip_joint" />
    <actuatorfrc name="fr_hip_joint_f" actuator="fr_hip_joint" noise="0.001" />
    <actuatorpos name="fr_knee_joint_p" actuator="fr_knee_joint" />
    <actuatorvel name="fr_knee_joint_v" actuator="fr_knee_joint" />
    <actuatorfrc name="fr_knee_joint_f" actuator="fr_knee_joint" noise="0.001" />
    <actuatorpos name="fr_thigh_joint_p" actuator="fr_thigh_joint" />
    <actuatorvel name="fr_thigh_joint_v" actuator="fr_thigh_joint" />
    <actuatorfrc name="fr_thigh_joint_f" actuator="fr_thigh_joint" noise="0.001" />
    <actuatorpos name="fl_hip_joint_p" actuator="fl_hip_joint" />
    <actuatorvel name="fl_hip_joint_v" actuator="fl_hip_joint" />
    <actuatorfrc name="fl_hip_joint_f" actuator="fl_hip_joint" noise="0.001" />
    <actuatorpos name="fl_knee_joint_p" actuator="fl_knee_joint" />
    <actuatorvel name="fl_knee_joint_v" actuator="fl_knee_joint" />
    <actuatorfrc name="fl_knee_joint_f" actuator="fl_knee_joint" noise="0.001" />
    <actuatorpos name="fl_thigh_joint_p" actuator="fl_thigh_joint" />
    <actuatorvel name="fl_thigh_joint_v" actuator="fl_thigh_joint" />
    <actuatorfrc name="fl_thigh_joint_f" actuator="fl_thigh_joint" noise="0.001" />
    <actuatorpos name="br_hip_joint_p" actuator="br_hip_joint" />
    <actuatorvel name="br_hip_joint_v" actuator="br_hip_joint" />
    <actuatorfrc name="br_hip_joint_f" actuator="br_hip_joint" noise="0.001" />
    <actuatorpos name="br_knee_joint_p" actuator="br_knee_joint" />
    <actuatorvel name="br_knee_joint_v" actuator="br_knee_joint" />
    <actuatorfrc name="br_knee_joint_f" actuator="br_knee_joint" noise="0.001" />
    <actuatorpos name="br_thigh_joint_p" actuator="br_thigh_joint" />
    <actuatorvel name="br_thigh_joint_v" actuator="br_thigh_joint" />
    <actuatorfrc name="br_thigh_joint_f" actuator="br_thigh_joint" noise="0.001" />
    <actuatorpos name="bl_hip_joint_p" actuator="bl_hip_joint" />
    <actuatorvel name="bl_hip_joint_v" actuator="bl_hip_joint" />
    <actuatorfrc name="bl_hip_joint_f" actuator="bl_hip_joint" noise="0.001" />
    <actuatorpos name="bl_knee_joint_p" actuator="bl_knee_joint" />
    <actuatorvel name="bl_knee_joint_v" actuator="bl_knee_joint" />
    <actuatorfrc name="bl_knee_joint_f" actuator="bl_knee_joint" noise="0.001" />
    <actuatorpos name="bl_thigh_joint_p" actuator="bl_thigh_joint" />
    <actuatorvel name="bl_thigh_joint_v" actuator="bl_thigh_joint" />
    <actuatorfrc name="bl_thigh_joint_f" actuator="bl_thigh_joint" noise="0.001" /> -->
    <framequat name="imu_sensor_quat" objtype="site" noise="0.001" objname="imu_sensor" />
    <gyro name="imu_sensor_gyro" site="imu_sensor" noise="0.005" cutoff="34.9" />
    <accelerometer name="imu_sensor_accel" site="imu_sensor"/> 
  </sensor>

</mujoco>