<?xml version="1.0" encoding="utf-8"?>

<robot name="dog">

  <!-- <link name="foot_print"/>
  <joint name="foot2base" type="fixed">
    <parent link="foot_print"/>
    <child link="base_link"/>
    <origin xyz="0 0 0.15" rpy = "0 0 0"/>
  </joint> -->


  <link
    name="base_link">
    <inertial>
      <origin
        xyz="-0.00116799019536368 -0.000173594149801448 -0.0010330556103498"
        rpy="0 0 0" />
      <mass
        value="3.79635843826293" />
      <inertia
        ixx="0.00653180532591732"
        ixy="-1.11416127424025E-06"
        ixz="-7.14254730089636E-08"
        iyy="0.00699486875003717"
        iyz="3.01555871343607E-09"
        izz="0.00601133855423796" />
    </inertial>
    <visual>
      <origin
        xyz="0 0 0"
        rpy="0 0 0" />
      <geometry>
        <mesh
           filename="package://descrip_pino/urdf/meshes/base_link.stl" />
      </geometry>
      <material
        name="">
        <color
          rgba="1 0.513725490196078 0.835294117647059 1" />
      </material>
    </visual>
    <collision>
      <origin
        xyz="0 0 0"
        rpy="0 0 0" />
      <geometry>
        <mesh
           filename="package://descrip_pino/urdf/meshes/base_link.stl" />
      </geometry>
    </collision>
  </link>
  <link
    name="fr_hip_Link">
    <inertial>
      <origin
        xyz="0.0627765891913514 -0.00732402137606836 0.00137350387141103"
        rpy="0 0 0" />
      <mass
        value="1.22881616014246" />
      <inertia
        ixx="0.000631292527188374"
        ixy="3.67662027694883E-07"
        ixz="-2.31045557920619E-06"
        iyy="0.00102652583112446"
        iyz="3.84306093913306E-07"
        izz="0.000645066715525604" />
    </inertial>
    <visual>
      <origin
        xyz="0 0 0"
        rpy="0 0 0" />
      <geometry>
        <mesh
           filename="package://descrip_pino/urdf/meshes/fr_hip_Link.stl" />
      </geometry>
      <material
        name="">
        <color
          rgba="1 0.301960784313725 0.137254901960784 1" />
      </material>
    </visual>
    <collision>
      <origin
        xyz="0 0 0"
        rpy="0 0 0" />
      <geometry>
        <mesh
           filename="package://descrip_pino/urdf/meshes/fr_hip_Link.stl" />
      </geometry>
    </collision>
  </link>
  <joint
    name="fr_hip_joint"
    type="revolute">
    <origin
      xyz="0.16425 -0.056271 0.0065998"
      rpy="0 0 -0.00019147" />
    <parent
      link="base_link" />
    <child
      link="fr_hip_Link" />
    <axis
      xyz="1 0 0" />
    <limit
      lower="-1.05"
      upper="1.05"
      effort="40"
      velocity="60" />
    <dynamics
      damping="0.01"
      friction="1" />
    <safety_controller
      soft_upper_limit="0.7"
      soft_lower_limit="-0.7"
      k_position="1"
      k_velocity="1" />
  </joint>
  <link
    name="fr_knee_Link">
    <inertial>
      <origin
        xyz="-0.00412725009080483 -0.0455480112536299 -0.0223222238234332"
        rpy="0 0 0" />
      <mass
        value="0.954665731651535" />
      <inertia
        ixx="0.00186475565836449"
        ixy="-2.79601068495168E-05"
        ixz="-0.000117267440722333"
        iyy="0.00242752674808599"
        iyz="-0.000165450621588276"
        izz="0.000721321647610568" />
    </inertial>
    <visual>
      <origin
        xyz="0 0 0"
        rpy="0 0 0" />
      <geometry>
        <mesh
           filename="package://descrip_pino/urdf/meshes/fr_knee_Link.stl" />
      </geometry>
      <material
        name="">
        <color
          rgba="0.898039215686275 0.917647058823529 0.929411764705882 1" />
      </material>
    </visual>
    <collision>
      <origin
        xyz="0 0 0"
        rpy="0 0 0" />
      <geometry>
        <mesh
           filename="package://descrip_pino/urdf/meshes/fr_knee_Link.stl" />
      </geometry>
    </collision>
  </link>
  <joint
    name="fr_knee_joint"
    type="revolute">
    <origin
      xyz="0.093 -0.0211 0.0019065"
      rpy="0 0 0" />
    <parent
      link="fr_hip_Link" />
    <child
      link="fr_knee_Link" />
    <axis
      xyz="0 1 0" />
    <limit
      lower="-0.7"
      upper="1.4"
      effort="40"
      velocity="60" />
    <dynamics
      damping="0.01"
      friction="1" />
    <safety_controller
      soft_upper_limit="1.4"
      soft_lower_limit="-0.7"
      k_position="1"
      k_velocity="1" />
  </joint>
  <link
    name="fr_thigh_Link">
    <inertial>
      <origin
        xyz="0.00802915937842624 1.74427164177371E-05 -0.100093112807725"
        rpy="0 0 0" />
      <mass
        value="0.102312763356514" />
      <inertia
        ixx="0.00063154856177368"
        ixy="2.66665866957018E-09"
        ixz="1.79399444282298E-05"
        iyy="0.000640821611514968"
        iyz="1.02190020967524E-07"
        izz="1.02238835213698E-05" />
    </inertial>
    <visual>
      <origin
        xyz="0 0 0"
        rpy="0 0 0" />
      <geometry>
        <mesh
           filename="package://descrip_pino/urdf/meshes/fr_thigh_Link.stl" />
      </geometry>
      <material
        name="">
        <color
          rgba="0.498039215686275 0.498039215686275 0.498039215686275 1" />
      </material>
    </visual>
    <collision>
      <origin
        xyz="0 0 0"
        rpy="0 0 0" />
      <geometry>
        <mesh
           filename="package://descrip_pino/urdf/meshes/fr_thigh_Link.stl" />
      </geometry>
    </collision>
  </link>
  <joint
    name="fr_thigh_joint"
    type="revolute">
    <origin
      xyz="0 -0.0609 -0.20735"
      rpy="0 0 0" />
    <parent
      link="fr_knee_Link" />
    <child
      link="fr_thigh_Link" />
    <axis
      xyz="0 1 0" />
    <limit
      lower="-2.44"
      upper="-0.83"
      effort="40"
      velocity="60" />
    <dynamics
      damping="0.01"
      friction="1" />
    <safety_controller
      soft_upper_limit="-0.83"
      soft_lower_limit="-2.44"
      k_position="1"
      k_velocity="1" />
  </joint>
  <link
    name="fl_hip_Link">
    <inertial>
      <origin
        xyz="0.0627765358969441 0.00765302314809621 -0.00137351911513577"
        rpy="0 0 0" />
      <mass
        value="1.22881742389137" />
      <inertia
        ixx="0.000631292707714591"
        ixy="-3.67698549791564E-07"
        ixz="2.31106298356401E-06"
        iyy="0.00102652463314235"
        iyz="3.84297175292907E-07"
        izz="0.000645065773792379" />
    </inertial>
    <visual>
      <origin
        xyz="0 0 0"
        rpy="0 0 0" />
      <geometry>
        <mesh
           filename="package://descrip_pino/urdf/meshes/fl_hip_Link.stl" />
      </geometry>
      <material
        name="">
        <color
          rgba="0.529411764705882 0.549019607843137 0.549019607843137 1" />
      </material>
    </visual>
    <collision>
      <origin
        xyz="0 0 0"
        rpy="0 0 0" />
      <geometry>
        <mesh
           filename="package://descrip_pino/urdf/meshes/fl_hip_Link.stl" />
      </geometry>
    </collision>
  </link>
  <joint
    name="fl_hip_joint"
    type="revolute">
    <origin
      xyz="0.16478 0.056229 0.0065999"
      rpy="0 0 -0.00019147" />
    <parent
      link="base_link" />
    <child
      link="fl_hip_Link" />
    <axis
      xyz="1 0 0" />
    <limit
      lower="-1.05"
      upper="1.05"
      effort="40"
      velocity="60" />
    <dynamics
      damping="0.01"
      friction="1" />
    <safety_controller
      soft_upper_limit="0.7"
      soft_lower_limit="-0.7"
      k_position="1"
      k_velocity="1" />
  </joint>
  <link
    name="fl_knee_Link">
    <inertial>
      <origin
        xyz="-0.00405628604914013 0.0455087651893473 -0.0222995983043919"
        rpy="0 0 0" />
      <mass
        value="0.954330307021386" />
      <inertia
        ixx="0.00186966839593566"
        ixy="2.8888612937339E-05"
        ixz="-0.000124479493853723"
        iyy="0.00243368281342031"
        iyz="0.000165899598157394"
        izz="0.000722653966087135" />
    </inertial>
    <visual>
      <origin
        xyz="0 0 0"
        rpy="0 0 0" />
      <geometry>
        <mesh
           filename="package://descrip_pino/urdf/meshes/fl_knee_Link.stl" />
      </geometry>
      <material
        name="">
        <color
          rgba="0.898039215686275 0.917647058823529 0.929411764705882 1" />
      </material>
    </visual>
    <collision>
      <origin
        xyz="0 0 0"
        rpy="0 0 0" />
      <geometry>
        <mesh
           filename="package://descrip_pino/urdf/meshes/fl_knee_Link.stl" />
      </geometry>
    </collision>
  </link>
  <joint
    name="fl_knee_joint"
    type="revolute">
    <origin
      xyz="0.093 0.0216 -0.0019065"
      rpy="0 0 0" />
    <parent
      link="fl_hip_Link" />
    <child
      link="fl_knee_Link" />
    <axis
      xyz="0 1 0" />
    <limit
      lower="-0.7"
      upper="1.4"
      effort="40"
      velocity="60" />
    <dynamics
      damping="0.01"
      friction="1" />
    <safety_controller
      soft_upper_limit="1.4"
      soft_lower_limit="-0.7"
      k_position="1"
      k_velocity="1" />
  </joint>
  <link
    name="fl_thigh_Link">
    <inertial>
      <origin
        xyz="0.00802923466667932 -0.00799683255686048 -0.100093139515383"
        rpy="0 0 0" />
      <mass
        value="0.102312565321635" />
      <inertia
        ixx="0.000631616656831354"
        ixy="-2.06179202513469E-09"
        ixz="1.79386806326537E-05"
        iyy="0.000640889732758803"
        iyz="-1.61919426051744E-07"
        izz="1.02238978474402E-05" />
    </inertial>
    <visual>
      <origin
        xyz="0 0 0"
        rpy="0 0 0" />
      <geometry>
        <mesh
           filename="package://descrip_pino/urdf/meshes/fl_thigh_Link.stl" />
      </geometry>
      <material
        name="">
        <color
          rgba="0.498039215686275 0.498039215686275 0.498039215686275 1" />
      </material>
    </visual>
    <collision>
      <origin
        xyz="0 0 0"
        rpy="0 0 0" />
      <geometry>
        <mesh
           filename="package://descrip_pino/urdf/meshes/fl_thigh_Link.stl" />
      </geometry>
    </collision>
  </link>
  <joint
    name="fl_thigh_joint"
    type="revolute">
    <origin
      xyz="0 0.0689 -0.20735"
      rpy="0 0 0" />
    <parent
      link="fl_knee_Link" />
    <child
      link="fl_thigh_Link" />
    <axis
      xyz="0 1 0" />
    <limit
      lower="-2.44"
      upper="-0.83"
      effort="40"
      velocity="60" />
    <dynamics
      damping="0.01"
      friction="1" />
    <safety_controller
      soft_upper_limit="-0.83"
      soft_lower_limit="-2.44"
      k_position="1"
      k_velocity="1" />
  </joint>
  <link
    name="br_hip_Link">
    <inertial>
      <origin
        xyz="-0.0627764275235256 -0.00732402694182105 -0.0013734252685203"
        rpy="0 0 0" />
      <mass
        value="1.2288141630314" />
      <inertia
        ixx="0.00063129214550813"
        ixy="-3.6743456585462E-07"
        ixz="-2.31042806499908E-06"
        iyy="0.00102652462204545"
        iyz="-3.84157955506349E-07"
        izz="0.000645066115091339" />
    </inertial>
    <visual>
      <origin
        xyz="0 0 0"
        rpy="0 0 0" />
      <geometry>
        <mesh
           filename="package://descrip_pino/urdf/meshes/br_hip_Link.stl" />
      </geometry>
      <material
        name="">
        <color
          rgba="1 0.301960784313725 0.137254901960784 1" />
      </material>
    </visual>
    <collision>
      <origin
        xyz="0 0 0"
        rpy="0 0 0" />
      <geometry>
        <mesh
           filename="package://descrip_pino/urdf/meshes/br_hip_Link.stl" />
      </geometry>
    </collision>
  </link>
  <joint
    name="br_hip_joint"
    type="revolute">
    <origin
      xyz="-0.16795 -0.056228 0.0067"
      rpy="0 0 -0.00019147" />
    <parent
      link="base_link" />
    <child
      link="br_hip_Link" />
    <axis
      xyz="1 0 0" />
    <limit
      lower="-1.05"
      upper="1.05"
      effort="40"
      velocity="60" />
    <dynamics
      damping="0.01"
      friction="1" />
    <safety_controller
      soft_upper_limit="0.7"
      soft_lower_limit="-0.7"
      k_position="1"
      k_velocity="1" />
  </joint>
  <link
    name="br_knee_Link">
    <inertial>
      <origin
        xyz="-0.00400975001715265 -0.0454196061928914 -0.0217568576725027"
        rpy="0 0 0" />
      <mass
        value="0.942891058030412" />
      <inertia
        ixx="0.00186440810823894"
        ixy="-2.79601184540589E-05"
        ixz="-0.000116878517215413"
        iyy="0.00242681712954829"
        iyz="-0.000165450534666229"
        izz="0.000720858758231732" />
    </inertial>
    <visual>
      <origin
        xyz="0 0 0"
        rpy="0 0 0" />
      <geometry>
        <mesh
           filename="package://descrip_pino/urdf/meshes/br_knee_Link.stl" />
      </geometry>
      <material
        name="">
        <color
          rgba="0.898039215686275 0.917647058823529 0.929411764705882 1" />
      </material>
    </visual>
    <collision>
      <origin
        xyz="0 0 0"
        rpy="0 0 0" />
      <geometry>
        <mesh
           filename="package://descrip_pino/urdf/meshes/br_knee_Link.stl" />
      </geometry>
    </collision>
  </link>
  <joint
    name="br_knee_joint"
    type="revolute">
    <origin
      xyz="-0.093 -0.0211 -0.0019064"
      rpy="0 0 0" />
    <parent
      link="br_hip_Link" />
    <child
      link="br_knee_Link" />
    <axis
      xyz="0 1 0" />
    <limit
      lower="-0.7"
      upper="1.4"
      effort="40"
      velocity="60" />
    <dynamics
      damping="0.01"
      friction="1" />
    <safety_controller
      soft_upper_limit="1.4"
      soft_lower_limit="-0.7"
      k_position="1"
      k_velocity="1" />
  </joint>
  <link
    name="br_thigh_Link">
    <inertial>
      <origin
        xyz="0.00802915937842674 1.74427164189583E-05 -0.100093112807641"
        rpy="0 0 0" />
      <mass
        value="0.102312763356646" />
      <inertia
        ixx="0.000631548561774211"
        ixy="2.66665867833189E-09"
        ixz="1.793994442838E-05"
        iyy="0.000640821611515542"
        iyz="1.02190020954049E-07"
        izz="1.02238835214126E-05" />
    </inertial>
    <visual>
      <origin
        xyz="0 0 0"
        rpy="0 0 0" />
      <geometry>
        <mesh
           filename="package://descrip_pino/urdf/meshes/br_thigh_Link.stl" />
      </geometry>
      <material
        name="">
        <color
          rgba="0.498039215686275 0.498039215686275 0.498039215686275 1" />
      </material>
    </visual>
    <collision>
      <origin
        xyz="0 0 0"
        rpy="0 0 0" />
      <geometry>
        <mesh
           filename="package://descrip_pino/urdf/meshes/br_thigh_Link.stl" />
      </geometry>
    </collision>
  </link>
  <joint
    name="br_thigh_joint"
    type="revolute">
    <origin
      xyz="0 -0.0609 -0.20735"
      rpy="0 0 0" />
    <parent
      link="br_knee_Link" />
    <child
      link="br_thigh_Link" />
    <axis
      xyz="0 1 0" />
    <limit
      lower="-2.44"
      upper="-0.83"
      effort="40"
      velocity="60" />
    <dynamics
      damping="0.01"
      friction="1" />
    <safety_controller
      soft_upper_limit="-0.83"
      soft_lower_limit="-2.44"
      k_position="1"
      k_velocity="1" />
  </joint>
  <link
    name="bl_hip_Link">
    <inertial>
      <origin
        xyz="-0.0627763928127562 0.00732401504497628 0.00137343527873432"
        rpy="0 0 0" />
      <mass
        value="1.22881684709264" />
      <inertia
        ixx="0.000631292448644309"
        ixy="3.67747906500063E-07"
        ixz="2.31082706601495E-06"
        iyy="0.00102652544836147"
        iyz="-3.84340906047479E-07"
        izz="0.00064506651120815" />
    </inertial>
    <visual>
      <origin
        xyz="0 0 0"
        rpy="0 0 0" />
      <geometry>
        <mesh
           filename="package://descrip_pino/urdf/meshes/bl_hip_Link.stl" />
      </geometry>
      <material
        name="">
        <color
          rgba="0.529411764705882 0.549019607843137 0.549019607843137 1" />
      </material>
    </visual>
    <collision>
      <origin
        xyz="0 0 0"
        rpy="0 0 0" />
      <geometry>
        <mesh
           filename="package://descrip_pino/urdf/meshes/bl_hip_Link.stl" />
      </geometry>
    </collision>
  </link>
  <joint
    name="bl_hip_joint"
    type="revolute">
    <origin
      xyz="-0.16792 0.056272 0.0067"
      rpy="0 0 -0.00019147" />
    <parent
      link="base_link" />
    <child
      link="bl_hip_Link" />
    <axis
      xyz="1 0 0" />
    <limit
      lower="-1.05"
      upper="1.05"
      effort="40"
      velocity="60" />
    <dynamics
      damping="0.01"
      friction="1" />
    <safety_controller
      soft_upper_limit="0.7"
      soft_lower_limit="-0.7"
      k_position="1"
      k_velocity="1" />
  </joint>
  <link
    name="bl_knee_Link">
    <inertial>
      <origin
        xyz="-0.00409868813521258 0.0455459705403089 -0.0223092739762113"
        rpy="0 0 0" />
      <mass
        value="0.954330235655386" />
      <inertia
        ixx="0.00186935549470052"
        ixy="2.88885860851926E-05"
        ixz="-0.000125358484414154"
        iyy="0.00243368278617631"
        iyz="0.000165899579243607"
        izz="0.000722966838340199" />
    </inertial>
    <visual>
      <origin
        xyz="0 0 0"
        rpy="0 0 0" />
      <geometry>
        <mesh
           filename="package://descrip_pino/urdf/meshes/bl_knee_Link.stl" />
      </geometry>
      <material
        name="">
        <color
          rgba="0.898039215686275 0.917647058823529 0.929411764705882 1" />
      </material>
    </visual>
    <collision>
      <origin
        xyz="0 0 0"
        rpy="0 0 0" />
      <geometry>
        <mesh
           filename="package://descrip_pino/urdf/meshes/bl_knee_Link.stl" />
      </geometry>
    </collision>
  </link>
  <joint
    name="bl_knee_joint"
    type="revolute">
    <origin
      xyz="-0.093 0.0211 0.0019064"
      rpy="0 0 0" />
    <parent
      link="bl_hip_Link" />
    <child
      link="bl_knee_Link" />
    <axis
      xyz="0 1 0" />
    <limit
      lower="-0.7"
      upper="1.4"
      effort="40"
      velocity="60" />
    <dynamics
      damping="0.01"
      friction="1" />
    <safety_controller
      soft_upper_limit="1.4"
      soft_lower_limit="-0.7"
      k_position="1"
      k_velocity="1" />
  </joint>
  <link
    name="bl_thigh_Link">
    <inertial>
      <origin
        xyz="0.0080292346666706 -0.00799683255686171 -0.100093139515354"
        rpy="0 0 0" />
      <mass
        value="0.102312565321635" />
      <inertia
        ixx="0.000631616656831351"
        ixy="-2.06179202954265E-09"
        ixz="1.7938680632658E-05"
        iyy="0.000640889732758812"
        iyz="-1.619194260572E-07"
        izz="1.02238978474551E-05" />
    </inertial>
    <visual>
      <origin
        xyz="0 0 0"
        rpy="0 0 0" />
      <geometry>
        <mesh
           filename="package://descrip_pino/urdf/meshes/bl_thigh_Link.stl" />
      </geometry>
      <material
        name="">
        <color
          rgba="0.498039215686275 0.498039215686275 0.498039215686275 1" />
      </material>
    </visual>
    <collision>
      <origin
        xyz="0 0 0"
        rpy="0 0 0" />
      <geometry>
        <mesh
           filename="package://descrip_pino/urdf/meshes/bl_thigh_Link.stl" />
      </geometry>
    </collision>
  </link>
  <joint
    name="bl_thigh_joint"
    type="revolute">
    <origin
      xyz="0 0.0689 -0.20735"
      rpy="0 0 0" />
    <parent
      link="bl_knee_Link" />
    <child
      link="bl_thigh_Link" />
    <axis
      xyz="0 1 0" />
    <limit
      lower="-2.44"
      upper="-0.83"
      effort="40"
      velocity="60" />
    <dynamics
      damping="0.01"
      friction="1" />
    <safety_controller
      soft_upper_limit="-0.83"
      soft_lower_limit="-2.44"
      k_position="1"
      k_velocity="1" />
  </joint>
</robot>