<?xml version="1.0" encoding="utf-8"?>

<robot name="dog">

  <link name="base">
    <inertial>
      <origin xyz="-0.00116799 -0.00017359 -0.00103305" rpy="0 0 0" />
      <mass value="4.5" />
      <inertia ixx="0.0138" ixy="0.0" ixz="0.0" iyy="0.0595" iyz="0.0" izz="0.0626" />
    </inertial>
    <visual>
      <origin xyz="0 0 0" rpy="0 0 0" />
      <geometry>
        <mesh filename="/home/ubuntu/meshes/base.stl" />
      </geometry>
      <material name=""><color rgba="1 0.513 0.835 1" /></material>
    </visual>
    <collision>
      <origin xyz="0 0 0" rpy="0 0 0" />
      <geometry>
        <box size="0.38 0.10 0.14" /> 
      </geometry>
    </collision>
  </link>

  <link name="fr_hip_Link">
    <inertial>
      <origin
        xyz="0.0627765891913514 -0.00732402137606836 0.00137350387141103"
        rpy="0 0 0" />
      <mass value="0.6" />
      <inertia ixx="0.00048" ixy="0" ixz="0" iyy="0.0006" iyz="0" izz="0.00048" />
    </inertial>
    <visual>
      <origin xyz="0 0 0" rpy="0 0 0" />
      <geometry><mesh filename="/home/ubuntu/meshes/fr_hip_Link.stl" /></geometry>
      <material name=""><color rgba="1 0.301 0.137 1" /></material>
    </visual>
    <collision>
      <origin xyz="0.06 0 0" rpy="1.5708 0 0" />
      <geometry>
        <cylinder length="0.06" radius="0.045" /> 
      </geometry>
    </collision>
  </link>

  <joint name="fr_hip_joint" type="revolute">
    <origin xyz="0.16425 -0.056271 0.0065998" rpy="0 0 -0.00019147" />
    <parent link="base" />
    <child link="fr_hip_Link" />
    <axis xyz="1 0 0" />
    <limit lower="-1.05" upper="1.05" effort="40" velocity="60" />
    <dynamics damping="0.05" friction="0.0" />
    <safety_controller soft_upper_limit="0.7" soft_lower_limit="-0.7" k_position="1" k_velocity="1" />
  </joint>

  <link name="fr_knee_Link">
    <inertial>
      <origin
        xyz="-0.00412725009080483 -0.0455480112536299 -0.0223222238234332"
        rpy="0 0 0" />
      <mass
        value="0.954665731651535" />
      <inertia
        ixx="0.00186475565836449"
        ixy="-2.79601068495168E-05"
        ixz="-0.000117267440722333"
        iyy="0.00242752674808599"
        iyz="-0.000165450621588276"
        izz="0.000721321647610568" />
    </inertial>
    <visual>
      <origin xyz="0 0 0" rpy="0 0 0" />
      <geometry><mesh filename="/home/ubuntu/meshes/fr_knee_Link.stl" /></geometry>
      <material name=""><color rgba="0.898 0.917 0.929 1" /></material>
    </visual>
    <collision>
      <origin xyz="-0.0041 -0.045 -0.02" rpy="0 0 0" />
      <geometry>
        <box size="0.08 0.05 0.15" />
      </geometry>
    </collision>
  </link>

  <joint name="fr_knee_joint" type="revolute">
    <origin xyz="0.093 -0.0211 0.0019065" rpy="0 0 0" />
    <parent link="fr_hip_Link" />
    <child link="fr_knee_Link" />
    <axis xyz="0 1 0" />
    <limit lower="-0.7" upper="1.4" effort="40" velocity="60" />
    <dynamics damping="0.05" friction="0.0" />
    <safety_controller soft_upper_limit="1.4" soft_lower_limit="-0.7" k_position="1" k_velocity="1" />
  </joint>

  <link name="fr_thigh_foot">
    <inertial>
      <origin
        xyz="0.00802915937842624 1.74427164177371E-05 -0.100093112807725"
        rpy="0 0 0" />
      <mass
        value="0.102312763356514" />
      <inertia
        ixx="0.00063154856177368"
        ixy="2.66665866957018E-09"
        ixz="1.79399444282298E-05"
        iyy="0.000640821611514968"
        iyz="1.02190020967524E-07"
        izz="1.02238835213698E-05" />
    </inertial>
    <visual>
      <origin xyz="0 0 0" rpy="0 0 0" />
      <geometry><mesh filename="/home/ubuntu/meshes/fr_thigh_foot.stl" /></geometry>
      <material name=""><color rgba="0.498 0.498 0.498 1" /></material>
    </visual>
    <collision>
      <origin xyz="0.008 0 -0.1" rpy="0 0 0" />
      <geometry>
        <cylinder length="0.18" radius="0.015" /> 
      </geometry>
    </collision>
    <collision>
      <origin xyz="0.008 0 -0.215" rpy="0 0 0" />
      <geometry>
        <sphere radius="0.026" />
      </geometry>
    </collision>
  </link>

  <joint name="fr_thigh_joint" type="revolute">
    <origin xyz="0 -0.0609 -0.20735" rpy="0 0 0" />
    <parent link="fr_knee_Link" />
    <child link="fr_thigh_foot" />
    <axis xyz="0 1 0" />
    <limit lower="-2.44" upper="-0.83" effort="40" velocity="60" />
    <dynamics damping="0.05" friction="0.0" />
    <safety_controller soft_upper_limit="-0.83" soft_lower_limit="-2.44" k_position="1" k_velocity="1" />
  </joint>

  <link name="fl_hip_Link">
    <inertial>
      <origin
        xyz="0.0627765358969441 0.00765302314809621 -0.00137351911513577"
        rpy="0 0 0" />
      <mass value="0.6" />
      <inertia ixx="0.00048" ixy="0" ixz="0" iyy="0.0006" iyz="0" izz="0.00048" />
    </inertial>
    <visual>
      <origin xyz="0 0 0" rpy="0 0 0" />
      <geometry><mesh filename="/home/ubuntu/meshes/fl_hip_Link.stl" /></geometry>
      <material name=""><color rgba="0.529 0.549 0.549 1" /></material>
    </visual>
    <collision>
      <origin xyz="0.06 0 0" rpy="1.5708 0 0" />
      <geometry><cylinder length="0.06" radius="0.045" /></geometry>
    </collision>
  </link>
  <joint name="fl_hip_joint" type="revolute">
    <origin xyz="0.16478 0.056229 0.0065999" rpy="0 0 -0.00019147" />
    <parent link="base" />
    <child link="fl_hip_Link" />
    <axis xyz="1 0 0" />
    <limit lower="-1.05" upper="1.05" effort="40" velocity="60" />
    <dynamics damping="0.05" friction="0.0" /> <safety_controller soft_upper_limit="0.7" soft_lower_limit="-0.7" k_position="1" k_velocity="1" />
  </joint>

  <link name="fl_knee_Link">
    <inertial>
      <origin
        xyz="-0.00405628604914013 0.0455087651893473 -0.0222995983043919"
        rpy="0 0 0" />
      <mass
        value="0.954330307021386" />
      <inertia
        ixx="0.00186966839593566"
        ixy="2.8888612937339E-05"
        ixz="-0.000124479493853723"
        iyy="0.00243368281342031"
        iyz="0.000165899598157394"
        izz="0.000722653966087135" />
    </inertial>
    <visual>
      <origin xyz="0 0 0" rpy="0 0 0" />
      <geometry><mesh filename="/home/ubuntu/meshes/fl_knee_Link.stl" /></geometry>
      <material name=""><color rgba="0.898 0.917 0.929 1" /></material>
    </visual>
    <collision>
      <origin xyz="-0.004 0.04 -0.02" rpy="0 0 0" />
      <geometry><box size="0.08 0.05 0.15" /></geometry>
    </collision>
  </link>
  <joint name="fl_knee_joint" type="revolute">
    <origin xyz="0.093 0.0216 -0.0019065" rpy="0 0 0" />
    <parent link="fl_hip_Link" />
    <child link="fl_knee_Link" />
    <axis xyz="0 1 0" />
    <limit lower="-0.7" upper="1.4" effort="40" velocity="60" />
    <dynamics damping="0.05" friction="0.0" /> <safety_controller soft_upper_limit="1.4" soft_lower_limit="-0.7" k_position="1" k_velocity="1" />
  </joint>

  <link name="fl_thigh_foot">
    <inertial>
      <origin
        xyz="0.00802923466667932 -0.00799683255686048 -0.100093139515383"
        rpy="0 0 0" />
      <mass
        value="0.102312565321635" />
      <inertia
        ixx="0.000631616656831354"
        ixy="-2.06179202513469E-09"
        ixz="1.79386806326537E-05"
        iyy="0.000640889732758803"
        iyz="-1.61919426051744E-07"
        izz="1.02238978474402E-05" />
    </inertial>
    <visual>
      <origin xyz="0 0 0" rpy="0 0 0" />
      <geometry><mesh filename="/home/ubuntu/meshes/fl_thigh_foot.stl" /></geometry>
      <material name=""><color rgba="0.498 0.498 0.498 1" /></material>
    </visual>
    <collision>
      <origin xyz="0.008 0 -0.1" rpy="0 0 0" />
      <geometry>
        <cylinder length="0.18" radius="0.015" /> 
      </geometry>
    </collision>
    <collision>
      <origin xyz="0.008 0 -0.215" rpy="0 0 0" />
      <geometry>
        <sphere radius="0.026" />
      </geometry>
    </collision>
  </link>
  <joint name="fl_thigh_joint" type="revolute">
    <origin xyz="0 0.0689 -0.20735" rpy="0 0 0" />
    <parent link="fl_knee_Link" />
    <child link="fl_thigh_foot" />
    <axis xyz="0 1 0" />
    <limit lower="-2.44" upper="-0.83" effort="40" velocity="60" />
    <dynamics damping="0.05" friction="0.0" /> <safety_controller soft_upper_limit="-0.83" soft_lower_limit="-2.44" k_position="1" k_velocity="1" />
  </joint>

  <link name="br_hip_Link">
    <inertial>
      <origin
        xyz="-0.0627764275235256 -0.00732402694182105 -0.0013734252685203"
        rpy="0 0 0" />
      <mass value="0.6" />
      <inertia ixx="0.00048" ixy="0" ixz="0" iyy="0.0006" iyz="0" izz="0.00048" />
    </inertial>
    <visual>
      <origin xyz="0 0 0" rpy="0 0 0" />
      <geometry><mesh filename="/home/ubuntu/meshes/br_hip_Link.stl" /></geometry>
      <material name=""><color rgba="1 0.301 0.137 1" /></material>
    </visual>
    <collision>
      <origin xyz="-0.06 0 0" rpy="1.5708 0 0" />
      <geometry><cylinder length="0.06" radius="0.045" /></geometry>
    </collision>
  </link>
  <joint name="br_hip_joint" type="revolute">
    <origin xyz="-0.16795 -0.056228 0.0067" rpy="0 0 -0.00019147" />
    <parent link="base" />
    <child link="br_hip_Link" />
    <axis xyz="1 0 0" />
    <limit lower="-1.05" upper="1.05" effort="40" velocity="60" />
    <dynamics damping="0.05" friction="0.0" /> <safety_controller soft_upper_limit="0.7" soft_lower_limit="-0.7" k_position="1" k_velocity="1" />
  </joint>

  <link name="br_knee_Link">
    <inertial>
      <origin
        xyz="-0.00400975001715265 -0.0454196061928914 -0.0217568576725027"
        rpy="0 0 0" />
      <mass
        value="0.942891058030412" />
      <inertia
        ixx="0.00186440810823894"
        ixy="-2.79601184540589E-05"
        ixz="-0.000116878517215413"
        iyy="0.00242681712954829"
        iyz="-0.000165450534666229"
        izz="0.000720858758231732" />
    </inertial>
    <visual>
      <origin xyz="0 0 0" rpy="0 0 0" />
      <geometry><mesh filename="/home/ubuntu/meshes/br_knee_Link.stl" /></geometry>
      <material name=""><color rgba="0.898 0.917 0.929 1" /></material>
    </visual>
    <collision>
      <origin xyz="-0.004 -0.04 -0.02" rpy="0 0 0" />
      <geometry><box size="0.08 0.05 0.15" /></geometry>
    </collision>
  </link>
  <joint name="br_knee_joint" type="revolute">
    <origin xyz="-0.093 -0.0211 -0.0019064" rpy="0 0 0" />
    <parent link="br_hip_Link" />
    <child link="br_knee_Link" />
    <axis xyz="0 1 0" />
    <limit lower="-0.7" upper="1.4" effort="40" velocity="60" />
    <dynamics damping="0.05" friction="0.0" /> <safety_controller soft_upper_limit="1.4" soft_lower_limit="-0.7" k_position="1" k_velocity="1" />
  </joint>

  <link name="br_thigh_foot">
    <inertial>
      <origin
        xyz="0.00802915937842674 1.74427164189583E-05 -0.100093112807641"
        rpy="0 0 0" />
      <mass
        value="0.102312763356646" />
      <inertia
        ixx="0.000631548561774211"
        ixy="2.66665867833189E-09"
        ixz="1.793994442838E-05"
        iyy="0.000640821611515542"
        iyz="1.02190020954049E-07"
        izz="1.02238835214126E-05" />
    </inertial>
    <visual>
      <origin xyz="0 0 0" rpy="0 0 0" />
      <geometry><mesh filename="/home/ubuntu/meshes/br_thigh_foot.stl" /></geometry>
      <material name=""><color rgba="0.498 0.498 0.498 1" /></material>
    </visual>
    <collision>
      <origin xyz="0.008 0 -0.1" rpy="0 0 0" />
      <geometry>
        <cylinder length="0.18" radius="0.015" /> 
      </geometry>
    </collision>

    <collision>
      <origin xyz="0.008 0 -0.215" rpy="0 0 0" />
      <geometry>
        <sphere radius="0.026" />
      </geometry>
    </collision>
  </link>
  <joint name="br_thigh_joint" type="revolute">
    <origin xyz="0 -0.0609 -0.20735" rpy="0 0 0" />
    <parent link="br_knee_Link" />
    <child link="br_thigh_foot" />
    <axis xyz="0 1 0" />
    <limit lower="-2.44" upper="-0.83" effort="40" velocity="60" />
    <dynamics damping="0.05" friction="0.0" /> <safety_controller soft_upper_limit="-0.83" soft_lower_limit="-2.44" k_position="1" k_velocity="1" />
  </joint>

  <link name="bl_hip_Link">
    <inertial>
      <origin
        xyz="-0.0627763928127562 0.00732401504497628 0.00137343527873432"
        rpy="0 0 0" />
      <mass value="0.6" />
      <inertia ixx="0.00048" ixy="0" ixz="0" iyy="0.0006" iyz="0" izz="0.00048" />
    </inertial>
    <visual>
      <origin xyz="0 0 0" rpy="0 0 0" />
      <geometry><mesh filename="/home/ubuntu/meshes/bl_hip_Link.stl" /></geometry>
      <material name=""><color rgba="0.529 0.549 0.549 1" /></material>
    </visual>
    <collision>
      <origin xyz="-0.06 0 0" rpy="1.5708 0 0" />
      <geometry><cylinder length="0.06" radius="0.045" /></geometry>
    </collision>
  </link>
  <joint name="bl_hip_joint" type="revolute">
    <origin xyz="-0.16792 0.056272 0.0067" rpy="0 0 -0.00019147" />
    <parent link="base" />
    <child link="bl_hip_Link" />
    <axis xyz="1 0 0" />
    <limit lower="-1.05" upper="1.05" effort="40" velocity="60" />
    <dynamics damping="0.05" friction="0.0" /> <safety_controller soft_upper_limit="0.7" soft_lower_limit="-0.7" k_position="1" k_velocity="1" />
  </joint>

  <link name="bl_knee_Link">
    <inertial>
      <origin
        xyz="-0.00409868813521258 0.0455459705403089 -0.0223092739762113"
        rpy="0 0 0" />
      <mass
        value="0.954330235655386" />
      <inertia
        ixx="0.00186935549470052"
        ixy="2.88885860851926E-05"
        ixz="-0.000125358484414154"
        iyy="0.00243368278617631"
        iyz="0.000165899579243607"
        izz="0.000722966838340199" />
    </inertial>
    <visual>
      <origin xyz="0 0 0" rpy="0 0 0" />
      <geometry><mesh filename="/home/ubuntu/meshes/bl_knee_Link.stl" /></geometry>
      <material name=""><color rgba="0.898 0.917 0.929 1" /></material>
    </visual>
    <collision>
      <origin xyz="-0.004 0.04 -0.02" rpy="0 0 0" />
      <geometry><box size="0.08 0.05 0.15" /></geometry>
    </collision>
  </link>
  <joint name="bl_knee_joint" type="revolute">
    <origin xyz="-0.093 0.0211 0.0019064" rpy="0 0 0" />
    <parent link="bl_hip_Link" />
    <child link="bl_knee_Link" />
    <axis xyz="0 1 0" />
    <limit lower="-0.7" upper="1.4" effort="40" velocity="60" />
    <dynamics damping="0.05" friction="0.0" /> <safety_controller soft_upper_limit="1.4" soft_lower_limit="-0.7" k_position="1" k_velocity="1" />
  </joint>

  <link name="bl_thigh_foot">
    <inertial>
      <origin
        xyz="0.0080292346666706 -0.00799683255686171 -0.100093139515354"
        rpy="0 0 0" />
      <mass
        value="0.102312565321635" />
      <inertia
        ixx="0.000631616656831351"
        ixy="-2.06179202954265E-09"
        ixz="1.7938680632658E-05"
        iyy="0.000640889732758812"
        iyz="-1.619194260572E-07"
        izz="1.02238978474551E-05" />
    </inertial>
    <visual>
      <origin xyz="0 0 0" rpy="0 0 0" />
      <geometry><mesh filename="/home/ubuntu/meshes/bl_thigh_foot.stl" /></geometry>
      <material name=""><color rgba="0.498 0.498 0.498 1" /></material>
    </visual>
    <collision>
      <origin xyz="0.008 0 -0.1" rpy="0 0 0" />
      <geometry>
        <cylinder length="0.18" radius="0.015" /> 
      </geometry>
    </collision>
    <collision>
      <origin xyz="0.008 0 -0.215" rpy="0 0 0" />
      <geometry>
        <sphere radius="0.026" />
      </geometry>
    </collision>
  </link>
  <joint name="bl_thigh_joint" type="revolute">
    <origin xyz="0 0.0689 -0.20735" rpy="0 0 0" />
    <parent link="bl_knee_Link" />
    <child link="bl_thigh_foot" />
    <axis xyz="0 1 0" />
    <limit lower="-2.44" upper="-0.83" effort="40" velocity="60" />
    <dynamics damping="0.05" friction="0.0" /> <safety_controller soft_upper_limit="-0.83" soft_lower_limit="-2.44" k_position="1" k_velocity="1" />
  </joint>

</robot>